INFO:werkzeug:127.0.0.1 - - [05/Oct/2024 17:25:32] "GET /admin/manage_entries HTTP/1.1" 500 -
Traceback (most recent call last):
  File "/home/runner/workspace/.pythonlibs/lib/python3.11/site-packages/flask/app.py", line 1498, in __call__
    return self.wsgi_app(environ, start_response)
           ^^^^^^^^^^^^^^^^^^^^^^^^^^^^^^^^^^^^^^
  File "/home/runner/workspace/.pythonlibs/lib/python3.11/site-packages/flask/app.py", line 1476, in wsgi_app
    response = self.handle_exception(e)
               ^^^^^^^^^^^^^^^^^^^^^^^^
  File "/home/runner/workspace/.pythonlibs/lib/python3.11/site-packages/flask/app.py", line 1473, in wsgi_app
    response = self.full_dispatch_request()
               ^^^^^^^^^^^^^^^^^^^^^^^^^^^^
  File "/home/runner/workspace/.pythonlibs/lib/python3.11/site-packages/flask/app.py", line 882, in full_dispatch_request
    rv = self.handle_user_exception(e)
         ^^^^^^^^^^^^^^^^^^^^^^^^^^^^^
  File "/home/runner/workspace/.pythonlibs/lib/python3.11/site-packages/flask/app.py", line 880, in full_dispatch_request
    rv = self.dispatch_request()
         ^^^^^^^^^^^^^^^^^^^^^^^
  File "/home/runner/workspace/.pythonlibs/lib/python3.11/site-packages/flask/app.py", line 865, in dispatch_request
    return self.ensure_sync(self.view_functions[rule.endpoint])(**view_args)  # type: ignore[no-any-return]
           ^^^^^^^^^^^^^^^^^^^^^^^^^^^^^^^^^^^^^^^^^^^^^^^^^^^^^^^^^^^^^^^^^^^^^^^^^^^^^^^^^^^^^^^^^^^^^^^^
  File "/home/runner/workspace/.pythonlibs/lib/python3.11/site-packages/flask_login/utils.py", line 290, in decorated_view
    return current_app.ensure_sync(func)(*args, **kwargs)
           ^^^^^^^^^^^^^^^^^^^^^^^^^^^^^^^^^^^^^^^^^^^^^^
  File "/home/runner/workspace/utils/decorators.py", line 10, in decorated_function
    return f(*args, **kwargs)
           ^^^^^^^^^^^^^^^^^^
  File "/home/runner/workspace/routes/admin.py", line 27, in manage_entries
    return render_template('admin/manage_entries.html', entries=entries)
           ^^^^^^^^^^^^^^^^^^^^^^^^^^^^^^^^^^^^^^^^^^^^^^^^^^^^^^^^^^^^^
  File "/home/runner/workspace/.pythonlibs/lib/python3.11/site-packages/flask/templating.py", line 150, in render_template
    return _render(app, template, context)
           ^^^^^^^^^^^^^^^^^^^^^^^^^^^^^^^
  File "/home/runner/workspace/.pythonlibs/lib/python3.11/site-packages/flask/templating.py", line 131, in _render
    rv = template.render(context)
         ^^^^^^^^^^^^^^^^^^^^^^^^
  File "/home/runner/workspace/.pythonlibs/lib/python3.11/site-packages/jinja2/environment.py", line 1304, in render
    self.environment.handle_exception()
  File "/home/runner/workspace/.pythonlibs/lib/python3.11/site-packages/jinja2/environment.py", line 939, in handle_exception
    raise rewrite_traceback_stack(source=source)
  File "/home/runner/workspace/templates/admin/manage_entries.html", line 1, in top-level template code
    {% extends "base.html" %}
  File "/home/runner/workspace/templates/base.html", line 74, in top-level template code
    {% block content %}{% endblock %}
  File "/home/runner/workspace/templates/admin/manage_entries.html", line 23, in block 'content'
    <td>{{ entry.user.username }}</td>
  File "/home/runner/workspace/.pythonlibs/lib/python3.11/site-packages/jinja2/environment.py", line 487, in getattr
    return getattr(obj, attribute)
           ^^^^^^^^^^^^^^^^^^^^^^^
jinja2.exceptions.UndefinedError: 'flask_app.models.Entry object' has no attribute 'user'
INFO:werkzeug:127.0.0.1 - - [05/Oct/2024 17:25:32] "GET /admin/manage_entries?__debugger__=yes&cmd=resource&f=style.css HTTP/1.1" 200 -
INFO:werkzeug:127.0.0.1 - - [05/Oct/2024 17:25:32] "GET /admin/manage_entries?__debugger__=yes&cmd=resource&f=debugger.js HTTP/1.1" 200 -